<?xml version="1.0" ?>
<robot name="solo">
  <link name="HFE">
    <visual>
      <origin rpy="0 0 0" xyz="0.01950 0 0"/>
      <geometry>
        <mesh filename="file://solo_leg/meshes/solo12_hip_fe_fr.stl"/>
      </geometry>
      <material name="grey">
        <color rgba="0.8 0.8 0.8 1.0"/>
      </material>
    </visual>
    <collision>
      <origin rpy="0 0 0" xyz="0.01950 0 0"/>
      <geometry>
        <mesh filename="file://solo_leg/meshes/solo12_hip_fe_fr.stl"/>
      </geometry>
      <material name="grey">
        <color rgba="0.8 0.8 0.8 1.0"/>
      </material>
    </collision>

    <!-- The HFE motor should be clamped to the table -->
    <!-- <inertial>
      <mass value="0.14853845"/>
      <origin rpy="0 0 0" xyz="-0.07870700 -0.01 0."/>
      <inertia ixx="0.00003024" ixy="-0.00004671" ixz="0.0" iyy="0.00041193" iyz="0.0" izz="0.00041107"/>
    </inertial> -->
  </link>
  
  <joint name="HFE" type="revolute">
    <parent link="HFE"/>
    <child link="UPPER_LEG"/>

    <limit lower="-4.2" upper="1.57" effort="1000" velocity="100"/>
    <axis xyz="0 1 0"/>

    <!-- Origin of joint is in the front where the pulley attaches (small Y offset) -->
    <origin rpy="0 0 0" xyz="0 -0.014 0"/>
  </joint>

  <link name="UPPER_LEG">
    <inertial>
      <origin rpy="0 0 0" xyz="-0.00001377 -0.01935853 -0.07870700"/>
      <mass value="0.14853845"/>
      <inertia ixx="0.00041107" ixy="0.0" ixz="0.0" iyy="0.00041193" iyz="-0.00004671" izz="0.00003024"/>
    </inertial>

    <visual>
      <origin rpy="0 0 0" xyz="0 0 0"/>
      <geometry>
        <mesh filename="file://solo_leg/meshes/solo_upper_leg_right_side.stl"/>
      </geometry>
      <material name="grey">
        <color rgba="0.8 0.8 0.8 1.0"/>
      </material>
    </visual>

    <collision>
      <origin rpy="0 0 0" xyz="0 0 0"/>
      <geometry>
        <mesh filename="file://solo_leg/meshes/solo_upper_leg_right_side.stl"/>
      </geometry>
      <material name="grey">
        <color rgba="0.8 0.8 0.8 1.0"/>
      </material>
    </collision>
  </link>

  <joint name="KFE" type="revolute">
    <parent link="UPPER_LEG"/>
    <child link="LOWER_LEG"/>
    <limit lower="-6.28" upper="6.28" effort="1000" velocity="100"/>

    <!-- Origin at the other side of the actuator link -->
    <axis xyz="0 1 0"/>
    <origin rpy="0 0 0" xyz="0 -0.03745 -0.16"/>
  </joint>

  <link name="LOWER_LEG">
    <inertial>
      <origin rpy="0 0 0" xyz="0.0 -0.00787644 -0.08928215"/>
      <mass value="0.03070001"/>
      <inertia ixx="0.00012024" ixy="0.0" ixz="0.0" iyy="0.00012029" iyz="-0.00000305" izz="0.00000216"/>
    </inertial>

    <visual>
      <origin rpy="0 0 0" xyz="0 0 0"/>
      <geometry>
        <mesh filename="file://solo_leg/meshes/solo_lower_leg_right_side.stl"/>
      </geometry>
      <material name="grey">
        <color rgba="0.8 0.8 0.8 1.0"/>
      </material>
    </visual>

    <collision>
      <origin rpy="0 0 0" xyz="0 0 0"/>
      <geometry>
        <mesh filename="file://solo_leg/meshes/solo_lower_leg_right_side.stl"/>
      </geometry>
      <material name="grey">
        <color rgba="0.8 0.8 0.8 1.0"/>
      </material>
    </collision>
  </link>

  <!-- Joint converting from the top of the foot to the bottom part (middle of circle)-->
  <joint name="FOOT_FRAME" type="fixed">
    <parent link="LOWER_LEG"/>
    <child link="FOOT"/>
    <origin rpy="0 0 0" xyz="0 -0.008 -0.16"/>
  </joint>

  <!-- TODO: Change the foot to the one actually used (one part) -->
  <link name="FOOT">
    <inertial>
      <origin rpy="0 0 0" xyz="0 0 0.00035767"/>
      <mass value="0.00693606"/>
      <inertia ixx="0.00000057" ixy="0.0" ixz="0.0" iyy="0.00000084" iyz="0.0" izz="0.00000053"/>
    </inertial>
    <visual>
      <origin rpy="0 0 0" xyz="0 0 0"/>
      <geometry>
        <mesh filename="file://solo_leg/meshes/solo_foot.stl"/>
      </geometry>
      <material name="grey">
        <color rgba="0.8 0.8 0.8 1.0"/>
      </material>
    </visual>
    <collision>
      <origin rpy="0 0 0" xyz="0 0 0"/>
      <geometry>
        <mesh filename="file://solo_leg/meshes/solo_foot.stl"/>
      </geometry>
      <material name="grey">
        <color rgba="0.8 0.8 0.8 1.0"/>
      </material>
    </collision>
  </link>
</robot>
